Workbook

Sheet Email Cleaner
A1: Original Email Paste Here | B1: Cleaned Email | C1: Matched Bad Pattern | D1: Status | E1: Email Type | F1: Domain | G1: Clean # | H1: Removed # | I1: Gmail # | J1: Outlook # | K1: Domain #
B2: =LOWER(TRIM(A2)) | C2: =IF(B2="","",IFERROR(INDEX('Bad Patterns'!$A$2:$A$120,MATCH(1,INDEX(--ISNUMBER(SEARCH('Bad Patterns'!$A$2:$A$120,B2)),0),0)),"")) | D2: =IF(B2="","",IF(C2<>"","REMOVE","KEEP")) | E2: =IF(D2<>"KEEP","",IF(RIGHT(B2,10)="@gmail.com","Gmail",IF(OR(RIGHT(B2,12)="@outlook.com",RIGHT(B2,12)="@hotmail.com",RIGHT(B2,9)="@live.com"),"Outlook","Domain"))) | F2: =IF(B2="","",IFERROR(RIGHT(B2,LEN(B2)-FIND("@",B2)),"")) | G2: =IF(D2="KEEP",COUNTIF($D$2:D2,"KEEP"),"") | H2: =IF(D2="REMOVE",COUNTIF($D$2:D2,"REMOVE"),"") | I2: =IF(E2="Gmail",COUNTIF($E$2:E2,"Gmail"),"") | J2: =IF(E2="Outlook",COUNTIF($E$2:E2,"Outlook"),"") | K2: =IF(E2="Domain",COUNTIF($E$2:E2,"Domain"),"")
B3: =LOWER(TRIM(A3)) | C3: =IF(B3="","",IFERROR(INDEX('Bad Patterns'!$A$2:$A$120,MATCH(1,INDEX(--ISNUMBER(SEARCH('Bad Patterns'!$A$2:$A$120,B3)),0),0)),"")) | D3: =IF(B3="","",IF(C3<>"","REMOVE","KEEP")) | E3: =IF(D3<>"KEEP","",IF(RIGHT(B3,10)="@gmail.com","Gmail",IF(OR(RIGHT(B3,12)="@outlook.com",RIGHT(B3,12)="@hotmail.com",RIGHT(B3,9)="@live.com"),"Outlook","Domain"))) | F3: =IF(B3="","",IFERROR(RIGHT(B3,LEN(B3)-FIND("@",B3)),"")) | G3: =IF(D3="KEEP",COUNTIF($D$2:D3,"KEEP"),"") | H3: =IF(D3="REMOVE",COUNTIF($D$2:D3,"REMOVE"),"") | I3: =IF(E3="Gmail",COUNTIF($E$2:E3,"Gmail"),"") | J3: =IF(E3="Outlook",COUNTIF($E$2:E3,"Outlook"),"") | K3: =IF(E3="Domain",COUNTIF($E$2:E3,"Domain"),"")
B4: =LOWER(TRIM(A4)) | C4: =IF(B4="","",IFERROR(INDEX('Bad Patterns'!$A$2:$A$120,MATCH(1,INDEX(--ISNUMBER(SEARCH('Bad Patterns'!$A$2:$A$120,B4)),0),0)),"")) | D4: =IF(B4="","",IF(C4<>"","REMOVE","KEEP")) | E4: =IF(D4<>"KEEP","",IF(RIGHT(B4,10)="@gmail.com","Gmail",IF(OR(RIGHT(B4,12)="@outlook.com",RIGHT(B4,12)="@hotmail.com",RIGHT(B4,9)="@live.com"),"Outlook","Domain"))) | F4: =IF(B4="","",IFERROR(RIGHT(B4,LEN(B4)-FIND("@",B4)),"")) | G4: =IF(D4="KEEP",COUNTIF($D$2:D4,"KEEP"),"") | H4: =IF(D4="REMOVE",COUNTIF($D$2:D4,"REMOVE"),"") | I4: =IF(E4="Gmail",COUNTIF($E$2:E4,"Gmail"),"") | J4: =IF(E4="Outlook",COUNTIF($E$2:E4,"Outlook"),"") | K4: =IF(E4="Domain",COUNTIF($E$2:E4,"Domain"),"")
B5: =LOWER(TRIM(A5)) | C5: =IF(B5="","",IFERROR(INDEX('Bad Patterns'!$A$2:$A$120,MATCH(1,INDEX(--ISNUMBER(SEARCH('Bad Patterns'!$A$2:$A$120,B5)),0),0)),"")) | D5: =IF(B5="","",IF(C5<>"","REMOVE","KEEP")) | E5: =IF(D5<>"KEEP","",IF(RIGHT(B5,10)="@gmail.com","Gmail",IF(OR(RIGHT(B5,12)="@outlook.com",RIGHT(B5,12)="@hotmail.com",RIGHT(B5,9)="@live.com"),"Outlook","Domain"))) | F5: =IF(B5="","",IFERROR(RIGHT(B5,LEN(B5)-FIND("@",B5)),"")) | G5: =IF(D5="KEEP",COUNTIF($D$2:D5,"KEEP"),"") | H5: =IF(D5="REMOVE",COUNTIF($D$2:D5,"REMOVE"),"") | I5: =IF(E5="Gmail",COUNTIF($E$2:E5,"Gmail"),"") | J5: =IF(E5="Outlook",COUNTIF($E$2:E5,"Outlook"),"") | K5: =IF(E5="Domain",COUNTIF($E$2:E5,"Domain"),"")
B6: =LOWER(TRIM(A6)) | C6: =IF(B6="","",IFERROR(INDEX('Bad Patterns'!$A$2:$A$120,MATCH(1,INDEX(--ISNUMBER(SEARCH('Bad Patterns'!$A$2:$A$120,B6)),0),0)),"")) | D6: =IF(B6="","",IF(C6<>"","REMOVE","KEEP")) | E6: =IF(D6<>"KEEP","",IF(RIGHT(B6,10)="@gmail.com","Gmail",IF(OR(RIGHT(B6,12)="@outlook.com",RIGHT(B6,12)="@hotmail.com",RIGHT(B6,9)="@live.com"),"Outlook","Domain"))) | F6: =IF(B6="","",IFERROR(RIGHT(B6,LEN(B6)-FIND("@",B6)),"")) | G6: =IF(D6="KEEP",COUNTIF($D$2:D6,"KEEP"),"") | H6: =IF(D6="REMOVE",COUNTIF($D$2:D6,"REMOVE"),"") | I6: =IF(E6="Gmail",COUNTIF($E$2:E6,"Gmail"),"") | J6: =IF(E6="Outlook",COUNTIF($E$2:E6,"Outlook"),"") | K6: =IF(E6="Domain",COUNTIF($E$2:E6,"Domain"),"")
B7: =LOWER(TRIM(A7)) | C7: =IF(B7="","",IFERROR(INDEX('Bad Patterns'!$A$2:$A$120,MATCH(1,INDEX(--ISNUMBER(SEARCH('Bad Patterns'!$A$2:$A$120,B7)),0),0)),"")) | D7: =IF(B7="","",IF(C7<>"","REMOVE","KEEP")) | E7: =IF(D7<>"KEEP","",IF(RIGHT(B7,10)="@gmail.com","Gmail",IF(OR(RIGHT(B7,12)="@outlook.com",RIGHT(B7,12)="@hotmail.com",RIGHT(B7,9)="@live.com"),"Outlook","Domain"))) | F7: =IF(B7="","",IFERROR(RIGHT(B7,LEN(B7)-FIND("@",B7)),"")) | G7: =IF(D7="KEEP",COUNTIF($D$2:D7,"KEEP"),"") | H7: =IF(D7="REMOVE",COUNTIF($D$2:D7,"REMOVE"),"") | I7: =IF(E7="Gmail",COUNTIF($E$2:E7,"Gmail"),"") | J7: =IF(E7="Outlook",COUNTIF($E$2:E7,"Outlook"),"") | K7: =IF(E7="Domain",COUNTIF($E$2:E7,"Domain"),"")
B8: =LOWER(TRIM(A8)) | C8: =IF(B8="","",IFERROR(INDEX('Bad Patterns'!$A$2:$A$120,MATCH(1,INDEX(--ISNUMBER(SEARCH('Bad Patterns'!$A$2:$A$120,B8)),0),0)),"")) | D8: =IF(B8="","",IF(C8<>"","REMOVE","KEEP")) | E8: =IF(D8<>"KEEP","",IF(RIGHT(B8,10)="@gmail.com","Gmail",IF(OR(RIGHT(B8,12)="@outlook.com",RIGHT(B8,12)="@hotmail.com",RIGHT(B8,9)="@live.com"),"Outlook","Domain"))) | F8: =IF(B8="","",IFERROR(RIGHT(B8,LEN(B8)-FIND("@",B8)),"")) | G8: =IF(D8="KEEP",COUNTIF($D$2:D8,"KEEP"),"") | H8: =IF(D8="REMOVE",COUNTIF($D$2:D8,"REMOVE"),"") | I8: =IF(E8="Gmail",COUNTIF($E$2:E8,"Gmail"),"") | J8: =IF(E8="Outlook",COUNTIF($E$2:E8,"Outlook"),"") | K8: =IF(E8="Domain",COUNTIF($E$2:E8,"Domain"),"")
B9: =LOWER(TRIM(A9)) | C9: =IF(B9="","",IFERROR(INDEX('Bad Patterns'!$A$2:$A$120,MATCH(1,INDEX(--ISNUMBER(SEARCH('Bad Patterns'!$A$2:$A$120,B9)),0),0)),"")) | D9: =IF(B9="","",IF(C9<>"","REMOVE","KEEP")) | E9: =IF(D9<>"KEEP","",IF(RIGHT(B9,10)="@gmail.com","Gmail",IF(OR(RIGHT(B9,12)="@outlook.com",RIGHT(B9,12)="@hotmail.com",RIGHT(B9,9)="@live.com"),"Outlook","Domain"))) | F9: =IF(B9="","",IFERROR(RIGHT(B9,LEN(B9)-FIND("@",B9)),"")) | G9: =IF(D9="KEEP",COUNTIF($D$2:D9,"KEEP"),"") | H9: =IF(D9="REMOVE",COUNTIF($D$2:D9,"REMOVE"),"") | I9: =IF(E9="Gmail",COUNTIF($E$2:E9,"Gmail"),"") | J9: =IF(E9="Outlook",COUNTIF($E$2:E9,"Outlook"),"") | K9: =IF(E9="Domain",COUNTIF($E$2:E9,"Domain"),"")
B10: =LOWER(TRIM(A10)) | C10: =IF(B10="","",IFERROR(INDEX('Bad Patterns'!$A$2:$A$120,MATCH(1,INDEX(--ISNUMBER(SEARCH('Bad Patterns'!$A$2:$A$120,B10)),0),0)),"")) | D10: =IF(B10="","",IF(C10<>"","REMOVE","KEEP")) | E10: =IF(D10<>"KEEP","",IF(RIGHT(B10,10)="@gmail.com","Gmail",IF(OR(RIGHT(B10,12)="@outlook.com",RIGHT(B10,12)="@hotmail.com",RIGHT(B10,9)="@live.com"),"Outlook","Domain"))) | F10: =IF(B10="","",IFERROR(RIGHT(B10,LEN(B10)-FIND("@",B10)),"")) | G10: =IF(D10="KEEP",COUNTIF($D$2:D10,"KEEP"),"") | H10: =IF(D10="REMOVE",COUNTIF($D$2:D10,"REMOVE"),"") | I10: =IF(E10="Gmail",COUNTIF($E$2:E10,"Gmail"),"") | J10: =IF(E10="Outlook",COUNTIF($E$2:E10,"Outlook"),"") | K10: =IF(E10="Domain",COUNTIF($E$2:E10,"Domain"),"")
B11: =LOWER(TRIM(A11)) | C11: =IF(B11="","",IFERROR(INDEX('Bad Patterns'!$A$2:$A$120,MATCH(1,INDEX(--ISNUMBER(SEARCH('Bad Patterns'!$A$2:$A$120,B11)),0),0)),"")) | D11: =IF(B11="","",IF(C11<>"","REMOVE","KEEP")) | E11: =IF(D11<>"KEEP","",IF(RIGHT(B11,10)="@gmail.com","Gmail",IF(OR(RIGHT(B11,12)="@outlook.com",RIGHT(B11,12)="@hotmail.com",RIGHT(B11,9)="@live.com"),"Outlook","Domain"))) | F11: =IF(B11="","",IFERROR(RIGHT(B11,LEN(B11)-FIND("@",B11)),"")) | G11: =IF(D11="KEEP",COUNTIF($D$2:D11,"KEEP"),"") | H11: =IF(D11="REMOVE",COUNTIF($D$2:D11,"REMOVE"),"") | I11: =IF(E11="Gmail",COUNTIF($E$2:E11,"Gmail"),"") | J11: =IF(E11="Outlook",COUNTIF($E$2:E11,"Outlook"),"") | K11: =IF(E11="Domain",COUNTIF($E$2:E11,"Domain"),"")
B12: =LOWER(TRIM(A12)) | C12: =IF(B12="","",IFERROR(INDEX('Bad Patterns'!$A$2:$A$120,MATCH(1,INDEX(--ISNUMBER(SEARCH('Bad Patterns'!$A$2:$A$120,B12)),0),0)),"")) | D12: =IF(B12="","",IF(C12<>"","REMOVE","KEEP")) | E12: =IF(D12<>"KEEP","",IF(RIGHT(B12,10)="@gmail.com","Gmail",IF(OR(RIGHT(B12,12)="@outlook.com",RIGHT(B12,12)="@hotmail.com",RIGHT(B12,9)="@live.com"),"Outlook","Domain"))) | F12: =IF(B12="","",IFERROR(RIGHT(B12,LEN(B12)-FIND("@",B12)),"")) | G12: =IF(D12="KEEP",COUNTIF($D$2:D12,"KEEP"),"") | H12: =IF(D12="REMOVE",COUNTIF($D$2:D12,"REMOVE"),"") | I12: =IF(E12="Gmail",COUNTIF($E$2:E12,"Gmail"),"") | J12: =IF(E12="Outlook",COUNTIF($E$2:E12,"Outlook"),"") | K12: =IF(E12="Domain",COUNTIF($E$2:E12,"Domain"),"")
B13: =LOWER(TRIM(A13)) | C13: =IF(B13="","",IFERROR(INDEX('Bad Patterns'!$A$2:$A$120,MATCH(1,INDEX(--ISNUMBER(SEARCH('Bad Patterns'!$A$2:$A$120,B13)),0),0)),"")) | D13: =IF(B13="","",IF(C13<>"","REMOVE","KEEP")) | E13: =IF(D13<>"KEEP","",IF(RIGHT(B13,10)="@gmail.com","Gmail",IF(OR(RIGHT(B13,12)="@outlook.com",RIGHT(B13,12)="@hotmail.com",RIGHT(B13,9)="@live.com"),"Outlook","Domain"))) | F13: =IF(B13="","",IFERROR(RIGHT(B13,LEN(B13)-FIND("@",B13)),"")) | G13: =IF(D13="KEEP",COUNTIF($D$2:D13,"KEEP"),"") | H13: =IF(D13="REMOVE",COUNTIF($D$2:D13,"REMOVE"),"") | I13: =IF(E13="Gmail",COUNTIF($E$2:E13,"Gmail"),"") | J13: =IF(E13="Outlook",COUNTIF($E$2:E13,"Outlook"),"") | K13: =IF(E13="Domain",COUNTIF($E$2:E13,"Domain"),"")
... B10001: =LOWER(TRIM(A10001)) | C10001: =IF(B10001="","",IFERROR(INDEX('Bad Patterns'!$A$2:$A$120,MATCH(1,INDEX(--ISNUMBER(SEARCH('Bad Patterns'!$A$2:$A$120,B10001)),0),0)),"")) | D10001: =IF(B10001="","",IF(C10001<>"","REMOVE","KEEP")) | E10001: =IF(D10001<>"KEEP","",IF(RIGHT(B10001,10)="@gmail.com","Gmail",IF(OR(RIGHT(B10001,12)="@outlook.com",RIGHT(B10001,12)="@hotmail.com",RIGHT(B10001,9)="@live.com"),"Outlook","Domain"))) | F10001: =IF(B10001="","",IFERROR(RIGHT(B10001,LEN(B10001)-FIND("@",B10001)),"")) | G10001: =IF(D10001="KEEP",COUNTIF($D$2:D10001,"KEEP"),"") | H10001: =IF(D10001="REMOVE",COUNTIF($D$2:D10001,"REMOVE"),"") | I10001: =IF(E10001="Gmail",COUNTIF($E$2:E10001,"Gmail"),"") | J10001: =IF(E10001="Outlook",COUNTIF($E$2:E10001,"Outlook"),"") | K10001: =IF(E10001="Domain",COUNTIF($E$2:E10001,"Domain"),"")

Sheet Bad Patterns
A1: Bad Pattern / Contains Text
A2: you@domain.com
A3: example@domain.com
A4: example@mysite.com
A5: wordpress@example.com
A6: your@email.com
A7: yourname@email.com
A8: john@company.com
A9: user@domain.com
A10: flags@2x.webp
A11: john@example.com
A12: john@email.com
... A120: mymail@mailservice.com

Sheet Clean Emails
A1: Copy Clean Emails From Here
A2: =IFERROR(INDEX('Email Cleaner'!$B$2:$B$10001,MATCH(1,'Email Cleaner'!$G$2:$G$10001,0)),"")
A3: =IFERROR(INDEX('Email Cleaner'!$B$2:$B$10001,MATCH(2,'Email Cleaner'!$G$2:$G$10001,0)),"")
A4: =IFERROR(INDEX('Email Cleaner'!$B$2:$B$10001,MATCH(3,'Email Cleaner'!$G$2:$G$10001,0)),"")
A5: =IFERROR(INDEX('Email Cleaner'!$B$2:$B$10001,MATCH(4,'Email Cleaner'!$G$2:$G$10001,0)),"")
A6: =IFERROR(INDEX('Email Cleaner'!$B$2:$B$10001,MATCH(5,'Email Cleaner'!$G$2:$G$10001,0)),"")
A7: =IFERROR(INDEX('Email Cleaner'!$B$2:$B$10001,MATCH(6,'Email Cleaner'!$G$2:$G$10001,0)),"")
A8: =IFERROR(INDEX('Email Cleaner'!$B$2:$B$10001,MATCH(7,'Email Cleaner'!$G$2:$G$10001,0)),"")
A9: =IFERROR(INDEX('Email Cleaner'!$B$2:$B$10001,MATCH(8,'Email Cleaner'!$G$2:$G$10001,0)),"")
A10: =IFERROR(INDEX('Email Cleaner'!$B$2:$B$10001,MATCH(9,'Email Cleaner'!$G$2:$G$10001,0)),"")
A11: =IFERROR(INDEX('Email Cleaner'!$B$2:$B$10001,MATCH(10,'Email Cleaner'!$G$2:$G$10001,0)),"")
A12: =IFERROR(INDEX('Email Cleaner'!$B$2:$B$10001,MATCH(11,'Email Cleaner'!$G$2:$G$10001,0)),"")
A13: =IFERROR(INDEX('Email Cleaner'!$B$2:$B$10001,MATCH(12,'Email Cleaner'!$G$2:$G$10001,0)),"")
A14: =IFERROR(INDEX('Email Cleaner'!$B$2:$B$10001,MATCH(13,'Email Cleaner'!$G$2:$G$10001,0)),"")
A15: =IFERROR(INDEX('Email Cleaner'!$B$2:$B$10001,MATCH(14,'Email Cleaner'!$G$2:$G$10001,0)),"")
A16: =IFERROR(INDEX('Email Cleaner'!$B$2:$B$10001,MATCH(15,'Email Cleaner'!$G$2:$G$10001,0)),"")
A17: =IFERROR(INDEX('Email Cleaner'!$B$2:$B$10001,MATCH(16,'Email Cleaner'!$G$2:$G$10001,0)),"")
A18: =IFERROR(INDEX('Email Cleaner'!$B$2:$B$10001,MATCH(17,'Email Cleaner'!$G$2:$G$10001,0)),"")
A19: =IFERROR(INDEX('Email Cleaner'!$B$2:$B$10001,MATCH(18,'Email Cleaner'!$G$2:$G$10001,0)),"")
A20: =IFERROR(INDEX('Email Cleaner'!$B$2:$B$10001,MATCH(19,'Email Cleaner'!$G$2:$G$10001,0)),"")
A21: =IFERROR(INDEX('Email Cleaner'!$B$2:$B$10001,MATCH(20,'Email Cleaner'!$G$2:$G$10001,0)),"")
A22: =IFERROR(INDEX('Email Cleaner'!$B$2:$B$10001,MATCH(21,'Email Cleaner'!$G$2:$G$10001,0)),"")
A23: =IFERROR(INDEX('Email Cleaner'!$B$2:$B$10001,MATCH(22,'Email Cleaner'!$G$2:$G$10001,0)),"")
A24: =IFERROR(INDEX('Email Cleaner'!$B$2:$B$10001,MATCH(23,'Email Cleaner'!$G$2:$G$10001,0)),"")
A25: =IFERROR(INDEX('Email Cleaner'!$B$2:$B$10001,MATCH(24,'Email Cleaner'!$G$2:$G$10001,0)),"")
A26: =IFERROR(INDEX('Email Cleaner'!$B$2:$B$10001,MATCH(25,'Email Cleaner'!$G$2:$G$10001,0)),"")
A27: =IFERROR(INDEX('Email Cleaner'!$B$2:$B$10001,MATCH(26,'Email Cleaner'!$G$2:$G$10001,0)),"")
A28: =IFERROR(INDEX('Email Cleaner'!$B$2:$B$10001,MATCH(27,'Email Cleaner'!$G$2:$G$10001,0)),"")
A29: =IFERROR(INDEX('Email Cleaner'!$B$2:$B$10001,MATCH(28,'Email Cleaner'!$G$2:$G$10001,0)),"")
A30: =IFERROR(INDEX('Email Cleaner'!$B$2:$B$10001,MATCH(29,'Email Cleaner'!$G$2:$G$10001,0)),"")
A31: =IFERROR(INDEX('Email Cleaner'!$B$2:$B$10001,MATCH(30,'Email Cleaner'!$G$2:$G$10001,0)),"")
A32: =IFERROR(INDEX('Email Cleaner'!$B$2:$B$10001,MATCH(31,'Email Cleaner'!$G$2:$G$10001,0)),"")
A33: =IFERROR(INDEX('Email Cleaner'!$B$2:$B$10001,MATCH(32,'Email Cleaner'!$G$2:$G$10001,0)),"")
A34: =IFERROR(INDEX('Email Cleaner'!$B$2:$B$10001,MATCH(33,'Email Cleaner'!$G$2:$G$10001,0)),"")
A35: =IFERROR(INDEX('Email Cleaner'!$B$2:$B$10001,MATCH(34,'Email Cleaner'!$G$2:$G$10001,0)),"")
A36: =IFERROR(INDEX('Email Cleaner'!$B$2:$B$10001,MATCH(35,'Email Cleaner'!$G$2:$G$10001,0)),"")
A37: =IFERROR(INDEX('Email Cleaner'!$B$2:$B$10001,MATCH(36,'Email Cleaner'!$G$2:$G$10001,0)),"")
A38: =IFERROR(INDEX('Email Cleaner'!$B$2:$B$10001,MATCH(37,'Email Cleaner'!$G$2:$G$10001,0)),"")
A39: =IFERROR(INDEX('Email Cleaner'!$B$2:$B$10001,MATCH(38,'Email Cleaner'!$G$2:$G$10001,0)),"")
A40: =IFERROR(INDEX('Email Cleaner'!$B$2:$B$10001,MATCH(39,'Email Cleaner'!$G$2:$G$10001,0)),"")
...

Sheet Removed Emails
A1: Copy Removed Emails From Here
A2: =IFERROR(INDEX('Email Cleaner'!$B$2:$B$10001,MATCH(1,'Email Cleaner'!$H$2:$H$10001,0)),"")
A3: =IFERROR(INDEX('Email Cleaner'!$B$2:$B$10001,MATCH(2,'Email Cleaner'!$H$2:$H$10001,0)),"")
A4: =IFERROR(INDEX('Email Cleaner'!$B$2:$B$10001,MATCH(3,'Email Cleaner'!$H$2:$H$10001,0)),"")
A5: =IFERROR(INDEX('Email Cleaner'!$B$2:$B$10001,MATCH(4,'Email Cleaner'!$H$2:$H$10001,0)),"")
A6: =IFERROR(INDEX('Email Cleaner'!$B$2:$B$10001,MATCH(5,'Email Cleaner'!$H$2:$H$10001,0)),"")
A7: =IFERROR(INDEX('Email Cleaner'!$B$2:$B$10001,MATCH(6,'Email Cleaner'!$H$2:$H$10001,0)),"")
A8: =IFERROR(INDEX('Email Cleaner'!$B$2:$B$10001,MATCH(7,'Email Cleaner'!$H$2:$H$10001,0)),"")
A9: =IFERROR(INDEX('Email Cleaner'!$B$2:$B$10001,MATCH(8,'Email Cleaner'!$H$2:$H$10001,0)),"")
A10: =IFERROR(INDEX('Email Cleaner'!$B$2:$B$10001,MATCH(9,'Email Cleaner'!$H$2:$H$10001,0)),"")
A11: =IFERROR(INDEX('Email Cleaner'!$B$2:$B$10001,MATCH(10,'Email Cleaner'!$H$2:$H$10001,0)),"")
A12: =IFERROR(INDEX('Email Cleaner'!$B$2:$B$10001,MATCH(11,'Email Cleaner'!$H$2:$H$10001,0)),"")
A13: =IFERROR(INDEX('Email Cleaner'!$B$2:$B$10001,MATCH(12,'Email Cleaner'!$H$2:$H$10001,0)),"")
A14: =IFERROR(INDEX('Email Cleaner'!$B$2:$B$10001,MATCH(13,'Email Cleaner'!$H$2:$H$10001,0)),"")
A15: =IFERROR(INDEX('Email Cleaner'!$B$2:$B$10001,MATCH(14,'Email Cleaner'!$H$2:$H$10001,0)),"")
A16: =IFERROR(INDEX('Email Cleaner'!$B$2:$B$10001,MATCH(15,'Email Cleaner'!$H$2:$H$10001,0)),"")
A17: =IFERROR(INDEX('Email Cleaner'!$B$2:$B$10001,MATCH(16,'Email Cleaner'!$H$2:$H$10001,0)),"")
A18: =IFERROR(INDEX('Email Cleaner'!$B$2:$B$10001,MATCH(17,'Email Cleaner'!$H$2:$H$10001,0)),"")
A19: =IFERROR(INDEX('Email Cleaner'!$B$2:$B$10001,MATCH(18,'Email Cleaner'!$H$2:$H$10001,0)),"")
A20: =IFERROR(INDEX('Email Cleaner'!$B$2:$B$10001,MATCH(19,'Email Cleaner'!$H$2:$H$10001,0)),"")
A21: =IFERROR(INDEX('Email Cleaner'!$B$2:$B$10001,MATCH(20,'Email Cleaner'!$H$2:$H$10001,0)),"")
A22: =IFERROR(INDEX('Email Cleaner'!$B$2:$B$10001,MATCH(21,'Email Cleaner'!$H$2:$H$10001,0)),"")
A23: =IFERROR(INDEX('Email Cleaner'!$B$2:$B$10001,MATCH(22,'Email Cleaner'!$H$2:$H$10001,0)),"")
A24: =IFERROR(INDEX('Email Cleaner'!$B$2:$B$10001,MATCH(23,'Email Cleaner'!$H$2:$H$10001,0)),"")
A25: =IFERROR(INDEX('Email Cleaner'!$B$2:$B$10001,MATCH(24,'Email Cleaner'!$H$2:$H$10001,0)),"")
A26: =IFERROR(INDEX('Email Cleaner'!$B$2:$B$10001,MATCH(25,'Email Cleaner'!$H$2:$H$10001,0)),"")
A27: =IFERROR(INDEX('Email Cleaner'!$B$2:$B$10001,MATCH(26,'Email Cleaner'!$H$2:$H$10001,0)),"")
A28: =IFERROR(INDEX('Email Cleaner'!$B$2:$B$10001,MATCH(27,'Email Cleaner'!$H$2:$H$10001,0)),"")
A29: =IFERROR(INDEX('Email Cleaner'!$B$2:$B$10001,MATCH(28,'Email Cleaner'!$H$2:$H$10001,0)),"")
A30: =IFERROR(INDEX('Email Cleaner'!$B$2:$B$10001,MATCH(29,'Email Cleaner'!$H$2:$H$10001,0)),"")
A31: =IFERROR(INDEX('Email Cleaner'!$B$2:$B$10001,MATCH(30,'Email Cleaner'!$H$2:$H$10001,0)),"")
A32: =IFERROR(INDEX('Email Cleaner'!$B$2:$B$10001,MATCH(31,'Email Cleaner'!$H$2:$H$10001,0)),"")
A33: =IFERROR(INDEX('Email Cleaner'!$B$2:$B$10001,MATCH(32,'Email Cleaner'!$H$2:$H$10001,0)),"")
A34: =IFERROR(INDEX('Email Cleaner'!$B$2:$B$10001,MATCH(33,'Email Cleaner'!$H$2:$H$10001,0)),"")
A35: =IFERROR(INDEX('Email Cleaner'!$B$2:$B$10001,MATCH(34,'Email Cleaner'!$H$2:$H$10001,0)),"")
A36: =IFERROR(INDEX('Email Cleaner'!$B$2:$B$10001,MATCH(35,'Email Cleaner'!$H$2:$H$10001,0)),"")
A37: =IFERROR(INDEX('Email Cleaner'!$B$2:$B$10001,MATCH(36,'Email Cleaner'!$H$2:$H$10001,0)),"")
A38: =IFERROR(INDEX('Email Cleaner'!$B$2:$B$10001,MATCH(37,'Email Cleaner'!$H$2:$H$10001,0)),"")
A39: =IFERROR(INDEX('Email Cleaner'!$B$2:$B$10001,MATCH(38,'Email Cleaner'!$H$2:$H$10001,0)),"")
A40: =IFERROR(INDEX('Email Cleaner'!$B$2:$B$10001,MATCH(39,'Email Cleaner'!$H$2:$H$10001,0)),"")
...

Sheet Gmail Emails
A1: Copy Gmail Emails From Here
A2: =IFERROR(INDEX('Email Cleaner'!$B$2:$B$10001,MATCH(1,'Email Cleaner'!$I$2:$I$10001,0)),"")
A3: =IFERROR(INDEX('Email Cleaner'!$B$2:$B$10001,MATCH(2,'Email Cleaner'!$I$2:$I$10001,0)),"")
A4: =IFERROR(INDEX('Email Cleaner'!$B$2:$B$10001,MATCH(3,'Email Cleaner'!$I$2:$I$10001,0)),"")
A5: =IFERROR(INDEX('Email Cleaner'!$B$2:$B$10001,MATCH(4,'Email Cleaner'!$I$2:$I$10001,0)),"")
A6: =IFERROR(INDEX('Email Cleaner'!$B$2:$B$10001,MATCH(5,'Email Cleaner'!$I$2:$I$10001,0)),"")
A7: =IFERROR(INDEX('Email Cleaner'!$B$2:$B$10001,MATCH(6,'Email Cleaner'!$I$2:$I$10001,0)),"")
A8: =IFERROR(INDEX('Email Cleaner'!$B$2:$B$10001,MATCH(7,'Email Cleaner'!$I$2:$I$10001,0)),"")
A9: =IFERROR(INDEX('Email Cleaner'!$B$2:$B$10001,MATCH(8,'Email Cleaner'!$I$2:$I$10001,0)),"")
A10: =IFERROR(INDEX('Email Cleaner'!$B$2:$B$10001,MATCH(9,'Email Cleaner'!$I$2:$I$10001,0)),"")
A11: =IFERROR(INDEX('Email Cleaner'!$B$2:$B$10001,MATCH(10,'Email Cleaner'!$I$2:$I$10001,0)),"")
A12: =IFERROR(INDEX('Email Cleaner'!$B$2:$B$10001,MATCH(11,'Email Cleaner'!$I$2:$I$10001,0)),"")
A13: =IFERROR(INDEX('Email Cleaner'!$B$2:$B$10001,MATCH(12,'Email Cleaner'!$I$2:$I$10001,0)),"")
A14: =IFERROR(INDEX('Email Cleaner'!$B$2:$B$10001,MATCH(13,'Email Cleaner'!$I$2:$I$10001,0)),"")
A15: =IFERROR(INDEX('Email Cleaner'!$B$2:$B$10001,MATCH(14,'Email Cleaner'!$I$2:$I$10001,0)),"")
A16: =IFERROR(INDEX('Email Cleaner'!$B$2:$B$10001,MATCH(15,'Email Cleaner'!$I$2:$I$10001,0)),"")
A17: =IFERROR(INDEX('Email Cleaner'!$B$2:$B$10001,MATCH(16,'Email Cleaner'!$I$2:$I$10001,0)),"")
A18: =IFERROR(INDEX('Email Cleaner'!$B$2:$B$10001,MATCH(17,'Email Cleaner'!$I$2:$I$10001,0)),"")
A19: =IFERROR(INDEX('Email Cleaner'!$B$2:$B$10001,MATCH(18,'Email Cleaner'!$I$2:$I$10001,0)),"")
A20: =IFERROR(INDEX('Email Cleaner'!$B$2:$B$10001,MATCH(19,'Email Cleaner'!$I$2:$I$10001,0)),"")
A21: =IFERROR(INDEX('Email Cleaner'!$B$2:$B$10001,MATCH(20,'Email Cleaner'!$I$2:$I$10001,0)),"")
A22: =IFERROR(INDEX('Email Cleaner'!$B$2:$B$10001,MATCH(21,'Email Cleaner'!$I$2:$I$10001,0)),"")
A23: =IFERROR(INDEX('Email Cleaner'!$B$2:$B$10001,MATCH(22,'Email Cleaner'!$I$2:$I$10001,0)),"")
A24: =IFERROR(INDEX('Email Cleaner'!$B$2:$B$10001,MATCH(23,'Email Cleaner'!$I$2:$I$10001,0)),"")
A25: =IFERROR(INDEX('Email Cleaner'!$B$2:$B$10001,MATCH(24,'Email Cleaner'!$I$2:$I$10001,0)),"")
A26: =IFERROR(INDEX('Email Cleaner'!$B$2:$B$10001,MATCH(25,'Email Cleaner'!$I$2:$I$10001,0)),"")
A27: =IFERROR(INDEX('Email Cleaner'!$B$2:$B$10001,MATCH(26,'Email Cleaner'!$I$2:$I$10001,0)),"")
A28: =IFERROR(INDEX('Email Cleaner'!$B$2:$B$10001,MATCH(27,'Email Cleaner'!$I$2:$I$10001,0)),"")
A29: =IFERROR(INDEX('Email Cleaner'!$B$2:$B$10001,MATCH(28,'Email Cleaner'!$I$2:$I$10001,0)),"")
A30: =IFERROR(INDEX('Email Cleaner'!$B$2:$B$10001,MATCH(29,'Email Cleaner'!$I$2:$I$10001,0)),"")
A31: =IFERROR(INDEX('Email Cleaner'!$B$2:$B$10001,MATCH(30,'Email Cleaner'!$I$2:$I$10001,0)),"")
A32: =IFERROR(INDEX('Email Cleaner'!$B$2:$B$10001,MATCH(31,'Email Cleaner'!$I$2:$I$10001,0)),"")
A33: =IFERROR(INDEX('Email Cleaner'!$B$2:$B$10001,MATCH(32,'Email Cleaner'!$I$2:$I$10001,0)),"")
A34: =IFERROR(INDEX('Email Cleaner'!$B$2:$B$10001,MATCH(33,'Email Cleaner'!$I$2:$I$10001,0)),"")
A35: =IFERROR(INDEX('Email Cleaner'!$B$2:$B$10001,MATCH(34,'Email Cleaner'!$I$2:$I$10001,0)),"")
A36: =IFERROR(INDEX('Email Cleaner'!$B$2:$B$10001,MATCH(35,'Email Cleaner'!$I$2:$I$10001,0)),"")
A37: =IFERROR(INDEX('Email Cleaner'!$B$2:$B$10001,MATCH(36,'Email Cleaner'!$I$2:$I$10001,0)),"")
A38: =IFERROR(INDEX('Email Cleaner'!$B$2:$B$10001,MATCH(37,'Email Cleaner'!$I$2:$I$10001,0)),"")
A39: =IFERROR(INDEX('Email Cleaner'!$B$2:$B$10001,MATCH(38,'Email Cleaner'!$I$2:$I$10001,0)),"")
A40: =IFERROR(INDEX('Email Cleaner'!$B$2:$B$10001,MATCH(39,'Email Cleaner'!$I$2:$I$10001,0)),"")
...

Sheet Outlook Emails
A1: Copy Outlook Emails From Here
A2: =IFERROR(INDEX('Email Cleaner'!$B$2:$B$10001,MATCH(1,'Email Cleaner'!$J$2:$J$10001,0)),"")
A3: =IFERROR(INDEX('Email Cleaner'!$B$2:$B$10001,MATCH(2,'Email Cleaner'!$J$2:$J$10001,0)),"")
A4: =IFERROR(INDEX('Email Cleaner'!$B$2:$B$10001,MATCH(3,'Email Cleaner'!$J$2:$J$10001,0)),"")
A5: =IFERROR(INDEX('Email Cleaner'!$B$2:$B$10001,MATCH(4,'Email Cleaner'!$J$2:$J$10001,0)),"")
A6: =IFERROR(INDEX('Email Cleaner'!$B$2:$B$10001,MATCH(5,'Email Cleaner'!$J$2:$J$10001,0)),"")
A7: =IFERROR(INDEX('Email Cleaner'!$B$2:$B$10001,MATCH(6,'Email Cleaner'!$J$2:$J$10001,0)),"")
A8: =IFERROR(INDEX('Email Cleaner'!$B$2:$B$10001,MATCH(7,'Email Cleaner'!$J$2:$J$10001,0)),"")
A9: =IFERROR(INDEX('Email Cleaner'!$B$2:$B$10001,MATCH(8,'Email Cleaner'!$J$2:$J$10001,0)),"")
A10: =IFERROR(INDEX('Email Cleaner'!$B$2:$B$10001,MATCH(9,'Email Cleaner'!$J$2:$J$10001,0)),"")
A11: =IFERROR(INDEX('Email Cleaner'!$B$2:$B$10001,MATCH(10,'Email Cleaner'!$J$2:$J$10001,0)),"")
A12: =IFERROR(INDEX('Email Cleaner'!$B$2:$B$10001,MATCH(11,'Email Cleaner'!$J$2:$J$10001,0)),"")
A13: =IFERROR(INDEX('Email Cleaner'!$B$2:$B$10001,MATCH(12,'Email Cleaner'!$J$2:$J$10001,0)),"")
A14: =IFERROR(INDEX('Email Cleaner'!$B$2:$B$10001,MATCH(13,'Email Cleaner'!$J$2:$J$10001,0)),"")
A15: =IFERROR(INDEX('Email Cleaner'!$B$2:$B$10001,MATCH(14,'Email Cleaner'!$J$2:$J$10001,0)),"")
A16: =IFERROR(INDEX('Email Cleaner'!$B$2:$B$10001,MATCH(15,'Email Cleaner'!$J$2:$J$10001,0)),"")
A17: =IFERROR(INDEX('Email Cleaner'!$B$2:$B$10001,MATCH(16,'Email Cleaner'!$J$2:$J$10001,0)),"")
A18: =IFERROR(INDEX('Email Cleaner'!$B$2:$B$10001,MATCH(17,'Email Cleaner'!$J$2:$J$10001,0)),"")
A19: =IFERROR(INDEX('Email Cleaner'!$B$2:$B$10001,MATCH(18,'Email Cleaner'!$J$2:$J$10001,0)),"")
A20: =IFERROR(INDEX('Email Cleaner'!$B$2:$B$10001,MATCH(19,'Email Cleaner'!$J$2:$J$10001,0)),"")
A21: =IFERROR(INDEX('Email Cleaner'!$B$2:$B$10001,MATCH(20,'Email Cleaner'!$J$2:$J$10001,0)),"")
A22: =IFERROR(INDEX('Email Cleaner'!$B$2:$B$10001,MATCH(21,'Email Cleaner'!$J$2:$J$10001,0)),"")
A23: =IFERROR(INDEX('Email Cleaner'!$B$2:$B$10001,MATCH(22,'Email Cleaner'!$J$2:$J$10001,0)),"")
A24: =IFERROR(INDEX('Email Cleaner'!$B$2:$B$10001,MATCH(23,'Email Cleaner'!$J$2:$J$10001,0)),"")
A25: =IFERROR(INDEX('Email Cleaner'!$B$2:$B$10001,MATCH(24,'Email Cleaner'!$J$2:$J$10001,0)),"")
A26: =IFERROR(INDEX('Email Cleaner'!$B$2:$B$10001,MATCH(25,'Email Cleaner'!$J$2:$J$10001,0)),"")
A27: =IFERROR(INDEX('Email Cleaner'!$B$2:$B$10001,MATCH(26,'Email Cleaner'!$J$2:$J$10001,0)),"")
A28: =IFERROR(INDEX('Email Cleaner'!$B$2:$B$10001,MATCH(27,'Email Cleaner'!$J$2:$J$10001,0)),"")
A29: =IFERROR(INDEX('Email Cleaner'!$B$2:$B$10001,MATCH(28,'Email Cleaner'!$J$2:$J$10001,0)),"")
A30: =IFERROR(INDEX('Email Cleaner'!$B$2:$B$10001,MATCH(29,'Email Cleaner'!$J$2:$J$10001,0)),"")
A31: =IFERROR(INDEX('Email Cleaner'!$B$2:$B$10001,MATCH(30,'Email Cleaner'!$J$2:$J$10001,0)),"")
A32: =IFERROR(INDEX('Email Cleaner'!$B$2:$B$10001,MATCH(31,'Email Cleaner'!$J$2:$J$10001,0)),"")
A33: =IFERROR(INDEX('Email Cleaner'!$B$2:$B$10001,MATCH(32,'Email Cleaner'!$J$2:$J$10001,0)),"")
A34: =IFERROR(INDEX('Email Cleaner'!$B$2:$B$10001,MATCH(33,'Email Cleaner'!$J$2:$J$10001,0)),"")
A35: =IFERROR(INDEX('Email Cleaner'!$B$2:$B$10001,MATCH(34,'Email Cleaner'!$J$2:$J$10001,0)),"")
A36: =IFERROR(INDEX('Email Cleaner'!$B$2:$B$10001,MATCH(35,'Email Cleaner'!$J$2:$J$10001,0)),"")
A37: =IFERROR(INDEX('Email Cleaner'!$B$2:$B$10001,MATCH(36,'Email Cleaner'!$J$2:$J$10001,0)),"")
A38: =IFERROR(INDEX('Email Cleaner'!$B$2:$B$10001,MATCH(37,'Email Cleaner'!$J$2:$J$10001,0)),"")
A39: =IFERROR(INDEX('Email Cleaner'!$B$2:$B$10001,MATCH(38,'Email Cleaner'!$J$2:$J$10001,0)),"")
A40: =IFERROR(INDEX('Email Cleaner'!$B$2:$B$10001,MATCH(39,'Email Cleaner'!$J$2:$J$10001,0)),"")
...

Sheet Domain Emails
A1: Copy Domain Emails From Here
A2: =IFERROR(INDEX('Email Cleaner'!$B$2:$B$10001,MATCH(1,'Email Cleaner'!$K$2:$K$10001,0)),"")
A3: =IFERROR(INDEX('Email Cleaner'!$B$2:$B$10001,MATCH(2,'Email Cleaner'!$K$2:$K$10001,0)),"")
A4: =IFERROR(INDEX('Email Cleaner'!$B$2:$B$10001,MATCH(3,'Email Cleaner'!$K$2:$K$10001,0)),"")
A5: =IFERROR(INDEX('Email Cleaner'!$B$2:$B$10001,MATCH(4,'Email Cleaner'!$K$2:$K$10001,0)),"")
A6: =IFERROR(INDEX('Email Cleaner'!$B$2:$B$10001,MATCH(5,'Email Cleaner'!$K$2:$K$10001,0)),"")
A7: =IFERROR(INDEX('Email Cleaner'!$B$2:$B$10001,MATCH(6,'Email Cleaner'!$K$2:$K$10001,0)),"")
A8: =IFERROR(INDEX('Email Cleaner'!$B$2:$B$10001,MATCH(7,'Email Cleaner'!$K$2:$K$10001,0)),"")
A9: =IFERROR(INDEX('Email Cleaner'!$B$2:$B$10001,MATCH(8,'Email Cleaner'!$K$2:$K$10001,0)),"")
A10: =IFERROR(INDEX('Email Cleaner'!$B$2:$B$10001,MATCH(9,'Email Cleaner'!$K$2:$K$10001,0)),"")
A11: =IFERROR(INDEX('Email Cleaner'!$B$2:$B$10001,MATCH(10,'Email Cleaner'!$K$2:$K$10001,0)),"")
A12: =IFERROR(INDEX('Email Cleaner'!$B$2:$B$10001,MATCH(11,'Email Cleaner'!$K$2:$K$10001,0)),"")
A13: =IFERROR(INDEX('Email Cleaner'!$B$2:$B$10001,MATCH(12,'Email Cleaner'!$K$2:$K$10001,0)),"")
A14: =IFERROR(INDEX('Email Cleaner'!$B$2:$B$10001,MATCH(13,'Email Cleaner'!$K$2:$K$10001,0)),"")
A15: =IFERROR(INDEX('Email Cleaner'!$B$2:$B$10001,MATCH(14,'Email Cleaner'!$K$2:$K$10001,0)),"")
A16: =IFERROR(INDEX('Email Cleaner'!$B$2:$B$10001,MATCH(15,'Email Cleaner'!$K$2:$K$10001,0)),"")
A17: =IFERROR(INDEX('Email Cleaner'!$B$2:$B$10001,MATCH(16,'Email Cleaner'!$K$2:$K$10001,0)),"")
A18: =IFERROR(INDEX('Email Cleaner'!$B$2:$B$10001,MATCH(17,'Email Cleaner'!$K$2:$K$10001,0)),"")
A19: =IFERROR(INDEX('Email Cleaner'!$B$2:$B$10001,MATCH(18,'Email Cleaner'!$K$2:$K$10001,0)),"")
A20: =IFERROR(INDEX('Email Cleaner'!$B$2:$B$10001,MATCH(19,'Email Cleaner'!$K$2:$K$10001,0)),"")
A21: =IFERROR(INDEX('Email Cleaner'!$B$2:$B$10001,MATCH(20,'Email Cleaner'!$K$2:$K$10001,0)),"")
A22: =IFERROR(INDEX('Email Cleaner'!$B$2:$B$10001,MATCH(21,'Email Cleaner'!$K$2:$K$10001,0)),"")
A23: =IFERROR(INDEX('Email Cleaner'!$B$2:$B$10001,MATCH(22,'Email Cleaner'!$K$2:$K$10001,0)),"")
A24: =IFERROR(INDEX('Email Cleaner'!$B$2:$B$10001,MATCH(23,'Email Cleaner'!$K$2:$K$10001,0)),"")
A25: =IFERROR(INDEX('Email Cleaner'!$B$2:$B$10001,MATCH(24,'Email Cleaner'!$K$2:$K$10001,0)),"")
A26: =IFERROR(INDEX('Email Cleaner'!$B$2:$B$10001,MATCH(25,'Email Cleaner'!$K$2:$K$10001,0)),"")
A27: =IFERROR(INDEX('Email Cleaner'!$B$2:$B$10001,MATCH(26,'Email Cleaner'!$K$2:$K$10001,0)),"")
A28: =IFERROR(INDEX('Email Cleaner'!$B$2:$B$10001,MATCH(27,'Email Cleaner'!$K$2:$K$10001,0)),"")
A29: =IFERROR(INDEX('Email Cleaner'!$B$2:$B$10001,MATCH(28,'Email Cleaner'!$K$2:$K$10001,0)),"")
A30: =IFERROR(INDEX('Email Cleaner'!$B$2:$B$10001,MATCH(29,'Email Cleaner'!$K$2:$K$10001,0)),"")
A31: =IFERROR(INDEX('Email Cleaner'!$B$2:$B$10001,MATCH(30,'Email Cleaner'!$K$2:$K$10001,0)),"")
A32: =IFERROR(INDEX('Email Cleaner'!$B$2:$B$10001,MATCH(31,'Email Cleaner'!$K$2:$K$10001,0)),"")
A33: =IFERROR(INDEX('Email Cleaner'!$B$2:$B$10001,MATCH(32,'Email Cleaner'!$K$2:$K$10001,0)),"")
A34: =IFERROR(INDEX('Email Cleaner'!$B$2:$B$10001,MATCH(33,'Email Cleaner'!$K$2:$K$10001,0)),"")
A35: =IFERROR(INDEX('Email Cleaner'!$B$2:$B$10001,MATCH(34,'Email Cleaner'!$K$2:$K$10001,0)),"")
A36: =IFERROR(INDEX('Email Cleaner'!$B$2:$B$10001,MATCH(35,'Email Cleaner'!$K$2:$K$10001,0)),"")
A37: =IFERROR(INDEX('Email Cleaner'!$B$2:$B$10001,MATCH(36,'Email Cleaner'!$K$2:$K$10001,0)),"")
A38: =IFERROR(INDEX('Email Cleaner'!$B$2:$B$10001,MATCH(37,'Email Cleaner'!$K$2:$K$10001,0)),"")
A39: =IFERROR(INDEX('Email Cleaner'!$B$2:$B$10001,MATCH(38,'Email Cleaner'!$K$2:$K$10001,0)),"")
A40: =IFERROR(INDEX('Email Cleaner'!$B$2:$B$10001,MATCH(39,'Email Cleaner'!$K$2:$K$10001,0)),"")
...

Sheet Dashboard
A1: Email Cleaning Dashboard
A3: Metric | B3: Count
A4: Total Pasted Emails | B4: =COUNTA('Email Cleaner'!A2:A10001)
A5: Clean Emails | B5: =COUNTIF('Email Cleaner'!D2:D10001,"KEEP")
A6: Removed Emails | B6: =COUNTIF('Email Cleaner'!D2:D10001,"REMOVE")
A7: Gmail Emails | B7: =COUNTIF('Email Cleaner'!E2:E10001,"Gmail")
A8: Outlook Emails | B8: =COUNTIF('Email Cleaner'!E2:E10001,"Outlook")
A9: Domain Emails | B9: =COUNTIF('Email Cleaner'!E2:E10001,"Domain")

Sheet How To Use
A1: How To Use This Fixed Template
A3: Step | B3: Instruction
A4: 1 | B4: Paste emails in Email Cleaner sheet, Column A, starting from A2.
A5: 2 | B5: Wait a few seconds for formulas to calculate. If results do not show, press Ctrl + Alt + F9.
A6: 3 | B6: Bad Patterns sheet contains the remove list. You can add more bad patterns in Column A.
A7: 4 | B7: Clean Emails sheet shows only emails marked KEEP.
A8: 5 | B8: Removed Emails sheet shows only emails marked REMOVE.
A9: 6 | B9: Gmail, Outlook, and Domain sheets show separated clean emails.
A10: 7 | B10: This version avoids FILTER and AGGREGATE. It uses helper columns with INDEX + MATCH for better compatibility.
A11: 8 | B11: When copying results, copy from the result sheet then use Paste Special > Values in your final file.
